<?xml version = "1.0"?>

<robot name="ixnaminki_olinki_arm" xmlns:xacro="http://www.ros.org/wiki/xacro">

    <xacro:include filename="$(find ixnaminki2_description)/urdf/arm_gazebo.xacro"/>
    <xacro:include filename="$(find ixnaminki2_description)/urdf/control_brazo.xacro"/>

    <xacro:property name="PI" value="3.14159265359"/>
    <xacro:property name="effort" value="30"/>
    <xacro:property name="velocity" value="5"/>
    <xacro:property name="escala" value="0.0015 0.0015 0.0015"/>
    <xacro:property name="esc" value="0.0015"/>
    <xacro:property name="Z" value="${0.0015/0.004}"/>

    <xacro:macro name="default_transmission" params="number">
        <transmission name="transmission_${number}">
            <plugin>transmission_interface/SimpleTransmission</plugin>
            <joint name="joint_${number}" role="joint_${number}">
                <mechanicalReduction>1.0</mechanicalReduction>
                <hardwareInterface>hardware_interface/PositionJointInterface</hardwareInterface>
            </joint>
            <actuator name="motor_${number}" role="actuator_${number}">
                <mechanicalReduction>1.0</mechanicalReduction>
                <hardwareInterface>hardware_interface/PositionJointInterface</hardwareInterface>
            </actuator>
        </transmission>
    </xacro:macro>

    <xacro:macro name="default_inertial" params="mass">
        <inertial>
            <origin xyz="0.0 0.0 0.0" rpy="0.0 0.0 0.0"/>
            <mass value="${mass}"/>
            <inertia ixx="0.0" ixy="0.0" ixz="0.0" 
                     iyy="0.0" iyz="0.0" 
                     izz="0.0"/>
        </inertial>
    </xacro:macro>

    <link name="world"/>

    <!-- CUERPO -->
    
    <link name="base_link">
        <xacro:default_inertial mass="5.0"/>
        <visual>
            <origin xyz="${-esc*50} ${esc*50} 0.0" rpy="1.570795 0.0 0.0"/>
            <geometry>
                <mesh filename="package://ixnaminki2_description/3DModels/BRAZO/Base.STL" scale="${escala}"/>
            </geometry>
            <material name="base00">
                <color rgba="0.5 0.3 0.2 0.8"/>
            </material>
        </visual>
        <collision>
            <origin xyz="${-esc*50} ${esc*50} 0.0" rpy="1.570795 0.0 0.0"/>
            <geometry>
                <mesh filename="package://ixnaminki2_description/3DModels/BRAZO/Base.STL" scale="${escala}"/>
            </geometry>
        </collision>
    </link>


    <link name="rotative_base">
        <xacro:default_inertial mass="5.0"/>
        <visual>
            <origin xyz="${-esc*47.5} ${esc*47.5} 0.0" rpy="1.570795 0.0 0.0"/>
            <geometry>
                <mesh filename="package://ixnaminki2_description/3DModels/BRAZO/RotBase.STL" scale="${escala}"/>
            </geometry>
            <material name="base01">
                <color rgba="0.5 0.5 0.5 0.5"/>
            </material>
        </visual>
        <collision>
            <origin xyz="${-esc*47.5} ${esc*47.5} 0.0" rpy="1.570795 0.0 0.0"/>
            <geometry>
                <mesh filename="package://ixnaminki2_description/3DModels/BRAZO/RotBase.STL" scale="${escala}"/>
            </geometry>
        </collision>
    </link>

    <link name="lower_arm">
        <xacro:default_inertial mass="5.0"/>
        <visual>
            <origin xyz="${-esc*12} ${esc*100} ${-esc*75}" rpy="1.570795 0.0 -0.27"/>
            <geometry>
                <mesh filename="package://ixnaminki2_description/3DModels/BRAZO/LowerArm.STL" scale="${escala}"/>
            </geometry>
            <material name="base02">
                <color rgba="1.0 0.1 0.1 0.7"/>
            </material>
        </visual>
        <collision>
            <origin xyz="${-esc*33} ${esc*100} ${esc*0}" rpy="1.570795 0.0 -0.27"/>
            <geometry>
                <mesh filename="package://ixnaminki2_description/3DModels/BRAZO/LowerArm.STL" scale="${escala}"/>
            </geometry>
        </collision>
    </link>

    <link name="upper_arm">
        <xacro:default_inertial mass="5.0"/>
        <visual>
            <origin xyz="${-esc*213.35} ${esc*133.75} ${-esc*472.7}" rpy="1.570795 0.0 -0.27"/>
            <geometry>
                <mesh filename="package://ixnaminki2_description/3DModels/BRAZO/UpperArm.STL" scale="${escala}"/>
            </geometry>
            <material name="base03">
                <color rgba="0.1 1.0 0.3 0.6"/>
            </material>
        </visual>
        <collision>
            <origin xyz="${-esc*213.35} ${esc*133.75} ${-esc*472.7}" rpy="1.570795 0.0 -0.27"/>
            <geometry>
                <mesh filename="package://ixnaminki2_description/3DModels/BRAZO/UpperArm.STL" scale="${escala}"/>
            </geometry>
        </collision>
    </link>
    
    <link name="rotative_arm">
        <xacro:default_inertial mass="5.0"/>
        <visual>
            <origin xyz="${-esc*113.8} ${-esc*515.0} ${-esc*170.0}" rpy="0.0 -0.25 0.59"/>
            <geometry>
                <mesh filename="package://ixnaminki2_description/3DModels/BRAZO/RotativeArm.STL" scale="${escala}"/>
            </geometry>
            <material name="base04">
                <color rgba="0.2 0.5 0.1 0.65"/>
            </material>
        </visual>
        <collision>
            <origin xyz="${-esc*113.8} ${-esc*515.0} ${-esc*170.0}" rpy="0.0 -0.25 0.59"/>
            <geometry>
                <mesh filename="package://ixnaminki2_description/3DModels/BRAZO/RotativeArm.STL" scale="${escala}"/>
            </geometry>
        </collision>
    </link>

    <link name="wrist">
        <xacro:default_inertial mass="1.0"/>
        <visual>
            <origin xyz="${-esc*297.72} ${-esc*510.0} ${-esc*200.0}" rpy="0.0 -0.25 0.6"/>
            <geometry>
                <mesh filename="package://ixnaminki2_description/3DModels/BRAZO/Wrist.STL" scale="${escala}"/>
            </geometry>
            <material name="base05">
                <color rgba="0.1 0.2 0.1 1"/>
            </material>
        </visual>
        <collision>
            <origin xyz="${-esc*297.72} ${-esc*510.0} ${-esc*200.0}" rpy="0.0 -0.25 0.6"/>
            <geometry>
                <mesh filename="package://ixnaminki2_description/3DModels/BRAZO/Wrist.STL" scale="${escala}"/>
            </geometry>
        </collision>
    </link>

    <link name="gripper_base">
        <xacro:default_inertial mass="1.0"/>
        <visual>
            <origin xyz="${esc*5} ${-esc*40} ${-esc*50}" rpy="0.0 0.0 0.0"/>
            <geometry>
                <mesh filename="package://ixnaminki2_description/3DModels/BRAZO/gripperFixed.STL" scale="${escala}"/>
            </geometry>
            <material name="base05"/>
        </visual>
        <collision>
            <origin xyz="${-esc*0} ${-esc*0} ${-esc*0}" rpy="0.0 -0.25 0.57"/>
            <geometry>
                <mesh filename="package://ixnaminki2_description/3DModels/BRAZO/gripperFixed.STL" scale="${escala}"/>
            </geometry>
        </collision>
    </link>

<!-- JOINTS  -->

    <joint name="virtual_joint" type="fixed">
        <parent link="world"/>
        <child link="base_link"/>
        <origin xyz="0 0 0" rpy="0 0 0"/>
    </joint> 
    <joint name="joint_base_rot" type="revolute">
        <parent link="base_link"/>
        <child link="rotative_base"/>
        <origin xyz="0.0 0.0 0.0" rpy="0.0 0.0 0.0"/>
        <axis xyz="0 0 1"/>
        <limit lower="-3.0" upper="3.0" effort="1.0" velocity="5.0"/>
    </joint>

    <joint name="joint_lower" type="revolute">
        <parent link="rotative_base"/>
        <child link="lower_arm"/>
        <origin xyz="0.0 0.0 ${esc*74}" rpy="0.0 0.0 0.3"/>
        <axis xyz="0 1 0"/>
        <limit lower="-3.0" upper="3.0" effort="1.0" velocity="5.0"/>
    </joint>

    <joint name="joint_upper" type="revolute">
        <parent link="lower_arm"/>
        <child link="upper_arm"/>
        <origin xyz="${esc*255.14} 0.0 ${esc*405.5}" rpy="0.0 0.0 0.0"/>
        <axis xyz="0 1 0"/>
        <limit lower="-3.0" upper="3.0" effort="1.0" velocity="5.0"/>
    </joint>
    <joint name="joint_rotative" type="revolute">
        <parent link="upper_arm"/>
        <child link="rotative_arm"/>
        <origin xyz="${esc*163.92} ${-esc*15} ${-esc*114.57}" rpy="0.0 0.53 0.0"/>
        <axis xyz="1 0 0"/>
        <limit lower="-3.0" upper="3.0" effort="1.0" velocity="5.0"/>
    </joint>

    <joint name="joint_extend_wrist" type="revolute">
        <parent link="rotative_arm"/>
        <child link="wrist"/>
        <origin xyz="${esc*176} 0 0" rpy="0 0 0"/>
        <axis xyz="0 1 0"/>
        <limit lower="-2.5" upper="1.0" effort="1.0" velocity="5.0"/>
    </joint>

    <joint name="joint_wrist_gripper" type="fixed">
        <parent link="wrist"/>
        <child link="gripper_base"/>
        <origin xyz="${esc*35} ${-esc*0} ${-esc*30}" rpy="0 0.8 0.0"/>
    </joint> 

    <xacro:default_transmission number="base_rot"/>
    <xacro:default_transmission number="lower"/>
    <xacro:default_transmission number="upper"/>
    <xacro:default_transmission number="rotative"/>

</robot>